Workbook

Sheet Dermatoses Bulleuses CNHU HKM
A1: _id | B1: start | C1: end | D1: today | E1: Âge (en mois) | F1: age_years_calc | G1: Sexe | H1: Profession | I1: Date de consultation | J1: Délai de consultation (en jours) | K1: Notion de prise médicamenteuse | L1: Préciser le ou les médicament(s) | M1: Type d'atteinte | N1: Surface corporelle atteinte | O1: Signes associés | P1: Préciser l'autre signe | Q1: Catégorie de la dermatose | R1: Dermatose Auto-immune | S1: Dermatose Infectieuse | T1: Toxidermie | U1: Dermatose Immunoallergique | V1: Préciser l'autre diagnostic
A2: 715501306 | B2: 46116.48 | C2: 46116.484 | D2: 46116 | E2: 1 | F2: 0.1 | G2: Homme | H2: Aucune | I2: 42397 | J2: 9 | K2: Non | M2: Cutanée seule | N2: 15 | O2: Autre | P2: Aucun | Q2: Infectieuse | S2: Épidermolyse staphylococcique
A3: 715512334 | B3: 46116.484 | C3: 46116.497 | D3: 46116 | E3: 468 | F3: 39 | G3: Femme | H3: Ménagère | I3: 42418 | J3: 14 | K3: Oui | L3: Amoxicilline | M3: Cutanée seule | N3: 5 | O3: Prurit | Q3: Toxidermie | T3: EPF Bulleux
A4: 715636712 | B4: 46116.497 | C4: 46116.632 | D4: 46116 | E4: 324 | F4: 27 | G4: Homme | H4: Sociologue | I4: 42451 | J4: 7 | K4: Oui | L4: Doxycycline CP,, nitrofurantoin cp | M4: Cutanée et muqueuse | N4: 3 | O4: Prurit | Q4: Toxidermie | T4: EPF Bulleux
A5: 715641743 | B5: 46116.632 | C5: 46116.637 | D5: 46116 | E5: 552 | F5: 46 | G5: Homme | H5: Commerçant | I5: 42388 | J5: 90 | K5: Non | M5: Cutanée seule | N5: 6 | O5: Prurit | Q5: Auto-immune | R5: Dermatose à IgA linéaire
A6: 718547936 | B6: 46119.907 | C6: 46119.952 | D6: 46119 | E6: 67 | F6: 5.6 | G6: Femme | H6: Enseignante | I6: 42929 | J6: 31 | K6: Oui | L6: Aerius cp,flagyl cp,lincocyne cp | M6: Cutanée seule | N6: 30 | O6: Autre | P6: Aucun | Q6: Auto-immune | R6: Pemphigoïde bulleuse
A7: 718789179 | B7: 46119.962 | C7: 46120.246 | D7: 46119 | E7: 552 | F7: 46 | G7: Femme | H7: Vendeuse | I7: 42765 | J7: 3 | K7: Oui | L7: Cotrimoxazole, ibuprofene, quinine, paracetamol, metronidazole | M7: Cutanée seule | N7: 45 | O7: Autre | P7: Aucun | Q7: Toxidermie | T7: Autre à préciser... | V7: Érythème pigmenté fixe
A8: 718806158 | B8: 46120.246 | C8: 46120.258 | D8: 46120 | E8: 516 | F8: 43 | G8: Homme | H8: Cultivateur | I8: 42744 | J8: 63 | K8: Oui | L8: Griseofilvine cp, polaramine cp, cetimizine cp, deslora denk, atarax 25mg | M8: Cutanée seule | N8: 80 | O8: Prurit Fièvre | Q8: Toxidermie | T8: Autre à préciser... | V8: Erytrodermie
A9: 718947052 | B9: 46120.258 | C9: 46120.345 | D9: 46120 | E9: 456 | F9: 38 | G9: Femme | H9: Coiffeuse | I9: 42740 | J9: 6 | K9: Non | M9: Cutanée seule | N9: 50 | O9: Autre | P9: Aucun | Q9: Toxidermie | T9: EPF Bulleux
A10: 719403589 | B10: 46120.345 | C10: 46120.661 | D10: 46120 | E10: 480 | F10: 40 | G10: Femme | H10: Vendeuse | I10: 42793 | J10: 2310 | K10: Oui | L10: Vitafer sirop, forcan 150mg, lorhist cp | M10: Cutanée et muqueuse | N10: 60 | O10: Prurit | Q10: Toxidermie | T10: Autre à préciser... | V10: Epidermolyse bulleuse acquise
A11: 719426805 | B11: 46120.661 | C11: 46120.676 | D11: 46120 | E11: 288 | F11: 24 | G11: Femme | H11: Agent commercial | I11: 42775 | J11: 93 | K11: Non | M11: Cutanée et muqueuse | N11: 2 | O11: Prurit | Q11: Infectieuse | S11: Autre à préciser... | V11: Érythème pigmenté fixe
A12: 722449196 | B12: 46120.676 | C12: 46123.962 | D12: 46120 | E12: 288 | F12: 24 | G12: Femme | H12: Agent commercial | I12: 42775 | J12: 124 | K12: Oui | L12: Duccay keylaneHD | M12: Cutanée et muqueuse | N12: 6 | O12: Autre | P12: Aucun | Q12: Toxidermie | T12: EPF Bulleux
A13: 722452001 | B13: 46123.962 | C13: 46123.972 | D13: 46123 | E13: 780 | F13: 65 | G13: Homme | H13: Cultivateur | I13: 42913 | J13: 93 | K13: Non | M13: Muqueuse seule | N13: 30 | O13: Douleur Fièvre | Q13: Auto-immune | R13: Pemphigoïde bulleuse
A14: 722479386 | B14: 46123.972 | C14: 46124.116 | D14: 46123 | E14: 780 | F14: 65 | G14: Homme | H14: Cultivateur | I14: 42913 | J14: 93 | K14: Non | M14: Cutanée et muqueuse | N14: 20 | O14: Fièvre Autre | P14: Plaies buccales | Q14: Auto-immune | R14: Pemphigoïde bulleuse
A15: 722480056 | B15: 46124.116 | C15: 46124.121 | D15: 46124 | E15: 504 | F15: 42 | G15: Femme | H15: Secrétaire | I15: 42632 | J15: 13 | K15: Oui | L15: Sérum anti tétanique, asmocet L cp | M15: Cutanée et muqueuse | N15: 7 | O15: Autre | P15: Aucun | Q15: Toxidermie | T15: Syndrome de Lyell
A16: 722480377 | B16: 46124.121 | C16: 46124.124 | D16: 46124 | E16: 480 | F16: 40 | G16: Femme | H16: Secrétaire | I16: 42570 | J16: 31 | K16: Non | M16: Cutanée seule | N16: 2 | O16: Autre | P16: Aucun | Q16: Toxidermie | T16: EPF Bulleux
A17: 722480792 | B17: 46124.124 | C17: 46124.127 | D17: 46124 | E17: 564 | F17: 47 | G17: Homme | H17: Technicien | I17: 42535 | J17: 6 | K17: Oui | L17: Forcan 150mg | M17: Cutanée seule | N17: 5 | O17: Autre | P17: Aucun | Q17: Toxidermie | T17: EPF Bulleux
A18: 722482063 | B18: 46124.127 | C18: 46124.134 | D18: 46124 | E18: 288 | F18: 24 | G18: Homme | H18: Pneumatique | I18: 42527 | J18: 4 | K18: Oui | L18: Ceftriaxone inj, gentamicine inj, celestene, Diclofénac, Polaramine | M18: Cutanée seule | N18: 9 | O18: Douleur Prurit | Q18: Toxidermie | T18: Syndrome de chevauchement
A19: 722619425 | B19: 46124.134 | C19: 46124.457 | D19: 46124 | E19: 252 | F19: 21 | G19: Femme | H19: Informaticienne | I19: 42717 | J19: 14 | K19: Oui | L19: Sédaspir cp, ibuprofen cp | M19: Cutanée seule | N19: 33 | O19: Fièvre | Q19: Toxidermie | T19: Syndrome de Stevens Johnson
A20: 722622203 | B20: 46124.457 | C20: 46124.462 | D20: 46124 | E20: 336 | F20: 28 | G20: Homme | H20: Fleuriste | I20: 42621 | J20: 385 | K20: Oui | L20: Griseofulvine, cloxacilline, flagyl cp, | M20: Cutanée et muqueuse | N20: 9 | O20: Autre | P20: Aucun | Q20: Infectieuse | S20: Autre à préciser... | V20: Epidermolyse bulleuse acquise
A21: 722625180 | B21: 46124.462 | C21: 46124.465 | D21: 46124 | E21: 720 | F21: 60 | G21: Femme | H21: Commerçante | I21: 42485 | J21: 3080 | K21: Oui | L21: Cloxacilline | M21: Cutanée seule | N21: 12 | O21: Autre | P21: Aucun | Q21: Toxidermie | T21: EPF Bulleux
A22: 722627814 | B22: 46124.465 | C22: 46124.469 | D22: 46124 | E22: 72 | F22: 6 | G22: Femme | H22: Écolière | I22: 42465 | J22: 7 | K22: Oui | L22: Amoxicilline cp, quinine cp, paracéamol 500mg, bactrim cp, fluconazole suspension, doprex collyre | M22: Cutanée et muqueuse | N22: 80 | O22: Autre | P22: Aucun | Q22: Toxidermie | T22: Syndrome de Stevens Johnson
A23: 722803352 | B23: 46116.637 | C23: 46124.737 | D23: 46116 | E23: 216 | F23: 18 | G23: Homme | H23: Élève | I23: 42830 | J23: 20 | K23: Oui | L23: Ciprofloxacin comprimés | M23: Cutanée seule | N23: 20 | O23: Prurit | Q23: Toxidermie | T23: Autre à préciser... | V23: Érythème polymorphe mineur
A24: 722805963 | B24: 46124.737 | C24: 46124.74 | D24: 46124 | E24: 288 | F24: 24 | G24: Homme | H24: Étudiant | I24: 43229 | J24: 730 | K24: Non | M24: Cutanée seule | N24: 40 | O24: Autre | P24: Aucun | Q24: Auto-immune | R24: Épidermolyse bulleuse acquise
A25: 722807402 | B25: 46124.74 | C25: 46124.742 | D25: 46124 | E25: 144 | F25: 12 | G25: Homme | H25: Écolier | I25: 43108 | J25: 6 | K25: Oui | L25: Phytothérapie | M25: Cutanée et muqueuse | N25: 35 | O25: Douleur | Q25: Toxidermie | T25: Syndrome de chevauchement
A26: 722809657 | B26: 46124.742 | C26: 46124.746 | D26: 46124 | E26: 120 | F26: 10 | G26: Homme | H26: Écolier | I26: 43214 | J26: 8 | K26: Non | M26: Cutanée et muqueuse | N26: 25 | O26: Autre | P26: Frissons | Q26: Toxidermie | T26: Syndrome de chevauchement
A27: 722811313 | B27: 46124.746 | C27: 46124.749 | D27: 46124 | E27: 636 | F27: 53 | G27: Femme | H27: Revendeuse | I27: 43060 | J27: 330 | K27: Non | M27: Cutanée seule | N27: 27 | O27: Prurit | Q27: Auto-immune | R27: Pemphigus paranéoplasique
A28: 722813656 | B28: 46124.749 | C28: 46124.753 | D28: 46124 | E28: 276 | F28: 23 | G28: Homme | H28: Étudiant | I28: 43074 | J28: 3 | K28: Oui | L28: Cotrimoxazole | M28: Cutanée et muqueuse | N28: 5 | O28: Douleur Autre | P28: Sensation de brulure | Q28: Toxidermie | T28: Syndrome de Stevens Johnson
A29: 722815699 | B29: 46124.753 | C29: 46124.757 | D29: 46124 | E29: 84 | F29: 7 | G29: Femme | H29: Écolière | I29: 42934 | J29: 15 | K29: Oui | L29: Amoxicilline, paracétamol cp | M29: Cutanée et muqueuse | N29: 10 | O29: Prurit Fièvre | Q29: Toxidermie | T29: Syndrome de Stevens Johnson
A30: 722818850 | B30: 46124.757 | C30: 46124.762 | D30: 46124 | E30: 36 | F30: 3 | G30: Homme | H30: Aucun | I30: 42901 | J30: 90 | K30: Non | M30: Cutanée seule | N30: 10 | O30: Prurit | Q30: Infectieuse | S30: Épidermolyse staphylococcique
A31: 722820234 | B31: 46124.762 | C31: 46124.765 | D31: 46124 | E31: 36 | F31: 3 | G31: Femme | H31: Aucune | I31: 42919 | J31: 8 | K31: Oui | L31: Coartem, aspirine | M31: Cutanée et muqueuse | N31: 10 | O31: Douleur | Q31: Toxidermie | T31: Syndrome de Stevens Johnson
A32: 722821710 | B32: 46124.765 | C32: 46124.767 | D32: 46124 | E32: 228 | F32: 19 | G32: Femme | H32: Étudiante | I32: 42789 | J32: 21 | K32: Non | M32: Cutanée seule | N32: 25 | O32: Douleur Prurit | Q32: Auto-immune | R32: Dermatite herpétiforme
A33: 722825333 | B33: 46124.767 | C33: 46124.775 | D33: 46124 | E33: 660 | F33: 55 | G33: Femme | H33: Technicienne de laboratoire | I33: 42845 | J33: 5 | K33: Oui | L33: Diclofenac comprimés | M33: Cutanée et muqueuse | N33: 27 | O33: Fièvre | Q33: Toxidermie | T33: Syndrome de chevauchement
A34: 722831716 | B34: 46124.775 | C34: 46124.79 | D34: 46124 | E34: 42 | F34: 3.5 | G34: Homme | H34: Aucune | I34: 42898 | J34: 30 | K34: Non | M34: Cutanée seule | N34: 10 | O34: Prurit | Q34: Infectieuse | S34: Impétigo bulleux
A35: 722832781 | B35: 46124.79 | C35: 46124.793 | D35: 46124 | E35: 372 | F35: 31 | G35: Femme | H35: Commerçante | I35: 42864 | J35: 3 | K35: Oui | L35: Phenobarbital, previscan, myorel, cortancyl | M35: Cutanée et muqueuse | N35: 27 | O35: Fièvre | Q35: Toxidermie | T35: Syndrome de chevauchement
A36: 722835688 | B36: 46124.793 | C36: 46124.798 | D36: 46124 | E36: 708 | F36: 59 | G36: Femme | H36: Retraité | I36: 42947 | J36: 2 | K36: Oui | L36: Xeloda, caprcitabine | M36: Cutanée seule | N36: 2 | O36: Prurit | Q36: Toxidermie | T36: EPF Bulleux
A37: 722837165 | B37: 46124.798 | C37: 46124.801 | D37: 46124 | E37: 216 | F37: 18 | G37: Femme | H37: Élève | I37: 43034 | J37: 7 | K37: Oui | L37: Sulfadoxine-pyriméthamine | M37: Cutanée et muqueuse | N37: 15 | O37: Prurit | Q37: Toxidermie | T37: Syndrome de Stevens Johnson
A38: 722839809 | B38: 46124.801 | C38: 46124.808 | D38: 46124 | E38: 132 | F38: 11 | G38: Homme | H38: Élève | I38: 42905 | J38: 4 | K38: Oui | L38: Sulfadoxine-pyriméthamine, amoxicilline, paracétamol | M38: Muqueuse seule | N38: 3 | O38: Douleur | Q38: Toxidermie | T38: Syndrome de Stevens Johnson
A39: 722904560 | B39: 46124.469 | C39: 46124.972 | D39: 46124 | E39: 636 | F39: 53 | G39: Homme | H39: Agent de PTT | I39: 42410 | J39: 62 | K39: Oui | L39: Erythromicine, flucoxacilline cp, cloxacilline cp | M39: Cutanée et muqueuse | N39: 95 | O39: Autre | P39: Aucun | Q39: Toxidermie | T39: Syndrome de Lyell
A40: 722905279 | B40: 46124.972 | C40: 46124.974 | D40: 46124 | E40: 60 | F40: 5 | G40: Homme | H40: Écolier | I40: 43465 | J40: 3 | K40: Oui | L40: Bactrim cp, paracétamol cp, vermifuge | M40: Cutanée et muqueuse | N40: 95 | O40: Douleur Prurit Fièvre | Q40: Toxidermie | T40: Syndrome de Lyell
...

Sheet Rapport_Etude
A1: RAPPORT D'ÉTUDE : DERMATOSES BULLEUSES AU CNHU HKM
A2: Structure IMRAD (Introduction, Méthodes, Résultats, And Discussion)
A4: 1. INTRODUCTION
A6: 1.1 Contexte et Justification
A7: Les dermatoses bulleuses constituent un groupe hétérogène d'affections cutanées caractérisées par la formation de bulles. Ces pathologies, bien que relativement rares, présentent un intérêt clinique majeur en raison de leur potentiel de gravité et de leur impact sur la qualité de vie des patients. Au Centre National Hospitalier Universitaire Hubert Koutoukou Maga (CNHU HKM) du Bénin, ces affections représentent une part significative des consultations dermatologiques.
A9: Cette étude vise à analyser le profil épidémiologique, clinique et étiologique des dermatoses bulleuses observées au CNHU HKM, afin d'identifier les facteurs de risque et les patterns cliniques caractéristiques de chaque catégorie diagnostique.
A11: 1.2 Objectifs de l'étude
A12: • Décrire les caractéristiques démographiques et cliniques des patients atteints de dermatoses bulleuses
A13: • Identifier les facteurs associés à chaque catégorie de dermatose (Toxidermie, Auto-immune, Infectieuse, Immunoallergique)
A14: • Évaluer les facteurs prédictifs de sévérité, notamment pour les toxidermies graves (Syndrome de Stevens-Johnson et Lyell)
A15: • Proposer une classification des patients par analyse de clustering
A16: • Formuler des recommandations pour la prise en charge clinique
... A21: 2.1 Type et cadre de l'étude
A22: Type d'étude: | B22: Étude transversale descriptive et analytique
A23: Lieu: | B23: Service de Dermatologie, CNHU HKM, Cotonou, Bénin
A24: Période: | B24: 2016-2019 (consultations de Janvier 2016 à Décembre 2018)
A25: Population: | B25: Patients présentant une dermatose bulleuse confirmée cliniquement
A27: 2.2 Population d'étude
A28: Effectif total analysé: | B28: =Rapport_Complet!B6 -> 130
A30: Critères d'inclusion:
A31: • Patients de tout âge consultant pour une dermatose bulleuse
A32: • Diagnostic clinique confirmé par un dermatologue
A33: • Dossier médical complet avec les variables d'intérêt
A35: 2.3 Variables étudiées (22 variables sources)
A36: Catégorie | B36: Variables | C36: Description
A37: Démographiques | B37: Âge, Sexe, Profession | C37: Caractéristiques socio-démographiques
A38: Temporelles | B38: Date consultation, Délai consultation | C38: Aspects chronologiques
A39: Médicamenteuses | B39: Prise médicamenteuse, Médicament(s) | C39: Exposition aux médicaments
A40: Cliniques | B40: Type d'atteinte, Surface corporelle, Signes associés | C40: Manifestations cliniques
A41: Diagnostiques | B41: Catégorie dermatose, Sous-types spécifiques | C41: Classification nosologique
A42: Dérivées | B42: Sévérité, Classes médicamenteuses, Groupe d'âge | C42: Variables calculées pour l'analyse
A44: 2.4 Analyses statistiques
A45: Méthode | B45: Application | C45: Logiciel
A46: Statistiques descriptives | B46: Moyennes, médianes, écart-types, IC 95% | C46: Excel + Python
A47: Test Chi² d'indépendance | B47: Association entre variables catégorielles | C47: Excel
A48: Régression logistique multivariée | B48: Facteurs prédictifs par catégorie de dermatose | C48: Python (statsmodels)
A49: Clustering K-Means | B49: Classification non supervisée (K=4 clusters) | C49: Python (scikit-learn)
A50: Clustering Hiérarchique | B50: Méthode de Ward avec distance de Gower | C50: Python (scipy)
A51: Indices de validation | B51: Silhouette, Calinski-Harabasz, Davies-Bouldin | C51: Python
A52: Seuil de significativité | B52: p < 0.05 | C52: -
...

Sheet Rapport_Complet
A1: RAPPORT DERMATOSES BULLEUSES CNHU HKM
A4: SECTION 1: POPULATION TOTALE
A6: Nombre total de répondants: | B6: =COUNTA('Dermatoses Bulleuses CNHU HKM'!A:A)-1 -> 130
A8: STATISTIQUES D'ÂGE (en années)
A9: Statistique | B9: Valeur
A10: Moyenne | B10: =AVERAGE('Dermatoses Bulleuses CNHU HKM'!F2:F131) -> 36.086923
A11: Médiane | B11: =MEDIAN('Dermatoses Bulleuses CNHU HKM'!F2:F131) -> 33
A12: Mode | B12: =_xlfn.MODE.SNGL('Dermatoses Bulleuses CNHU HKM'!F2:F131) -> 46
A13: Écart-type | B13: =_xlfn.STDEV.P('Dermatoses Bulleuses CNHU HKM'!F2:F131) -> 25.733801
A15: SEXE
A16: Valeur | B16: Fréquence | C16: Pourcentage
A17: Femme | B17: =COUNTIF('Dermatoses Bulleuses CNHU HKM'!G:G,"Femme") -> 74 | C17: =B17/$B$6*100 -> 56.923077
A18: Homme | B18: =COUNTIF('Dermatoses Bulleuses CNHU HKM'!G:G,"Homme") -> 56 | C18: =B18/$B$6*100 -> 43.076923
A20: NOTION DE PRISE MÉDICAMENTEUSE
A21: Valeur | B21: Fréquence | C21: Pourcentage
A22: Oui | B22: =COUNTIF('Dermatoses Bulleuses CNHU HKM'!K:K,"Oui") -> 68 | C22: =B22/$B$6*100 -> 52.307692
A23: Non | B23: =COUNTIF('Dermatoses Bulleuses CNHU HKM'!K:K,"Non") -> 62 | C23: =B23/$B$6*100 -> 47.692308
A25: TYPE D'ATTEINTE
A26: Valeur | B26: Fréquence | C26: Pourcentage
A27: Cutanée seule | B27: =COUNTIF('Dermatoses Bulleuses CNHU HKM'!M:M,"Cutanée seule") -> 67 | C27: =B27/$B$6*100 -> 51.538462
A28: Cutanée et muqueuse | B28: =COUNTIF('Dermatoses Bulleuses CNHU HKM'!M:M,"Cutanée et muqueuse") -> 60 | C28: =B28/$B$6*100 -> 46.153846
A29: Muqueuse seule | B29: =COUNTIF('Dermatoses Bulleuses CNHU HKM'!M:M,"Muqueuse seule") -> 3 | C29: =B29/$B$6*100 -> 2.3076923
A31: SURFACE CORPORELLE ATTEINTE
A32: Statistique | B32: Valeur
A33: Moyenne | B33: =AVERAGE('Dermatoses Bulleuses CNHU HKM'!N2:N131) -> 24.853846
A34: Médiane | B34: =MEDIAN('Dermatoses Bulleuses CNHU HKM'!N2:N131) -> 15
A35: Mode | B35: =_xlfn.MODE.SNGL('Dermatoses Bulleuses CNHU HKM'!N2:N131) -> 10
A36: Écart-type | B36: =_xlfn.STDEV.P('Dermatoses Bulleuses CNHU HKM'!N2:N131) -> 24.846022
A38: SIGNES ASSOCIÉS
A39: Valeur | B39: Fréquence | C39: Pourcentage
A40: Prurit | B40: {=SUMPRODUCT(--(ISNUMBER(SEARCH("Prurit",'Dermatoses Bulleuses CNHU HKM'!O2:O131))))} -> 71 | C40: =B40/$B$6*100 -> 54.615385
A41: Douleur | B41: {=SUMPRODUCT(--(ISNUMBER(SEARCH("Douleur",'Dermatoses Bulleuses CNHU HKM'!O2:O131))))} -> 55 | C41: =B41/$B$6*100 -> 42.307692
A42: Fièvre | B42: {=SUMPRODUCT(--(ISNUMBER(SEARCH("Fièvre",'Dermatoses Bulleuses CNHU HKM'!O2:O131))))} -> 18 | C42: =B42/$B$6*100 -> 13.846154
A43: Autre | B43: {=SUMPRODUCT(--(ISNUMBER(SEARCH("Autre",'Dermatoses Bulleuses CNHU HKM'!O2:O131))))} -> 25 | C43: =B43/$B$6*100 -> 19.230769
A45: CATÉGORIE DE LA DERMATOSE
A46: Valeur | B46: Fréquence | C46: Pourcentage
A47: Toxidermie | B47: =COUNTIF('Dermatoses Bulleuses CNHU HKM'!Q:Q,"Toxidermie") -> 75 | C47: =B47/$B$6*100 -> 57.692308
A48: Auto-immune | B48: =COUNTIF('Dermatoses Bulleuses CNHU HKM'!Q:Q,"Auto-immune") -> 31 | C48: =B48/$B$6*100 -> 23.846154
A49: Infectieuse | B49: =COUNTIF('Dermatoses Bulleuses CNHU HKM'!Q:Q,"Infectieuse") -> 19 | C49: =B49/$B$6*100 -> 14.615385
A50: Immunoallergique | B50: =COUNTIF('Dermatoses Bulleuses CNHU HKM'!Q:Q,"Immunoallergique") -> 5 | C50: =B50/$B$6*100 -> 3.8461538
...

Sheet Analyse_Statistique
A1: ANALYSE STATISTIQUE APPROFONDIE - DERMATOSES BULLEUSES CNHU HKM
A2: Analyse par Régression Logistique Multivariée pour chaque Catégorie de Dermatose
A4: SECTION 1: RÉSUMÉ STATISTIQUE DES DONNÉES
A6: Variable | B6: N | C6: Moyenne | D6: Médiane | E6: Écart-type | F6: Min | G6: Max | H6: IC 95% Inf | I6: IC 95% Sup
A7: Âge (années) | B7: =COUNTA('Dermatoses Bulleuses CNHU HKM'!F:F)-1 -> 130 | C7: =AVERAGE('Dermatoses Bulleuses CNHU HKM'!F2:F131) -> 36.086923 | D7: =MEDIAN('Dermatoses Bulleuses CNHU HKM'!F2:F131) -> 33 | E7: =_xlfn.STDEV.S('Dermatoses Bulleuses CNHU HKM'!F2:F131) -> 25.833352 | F7: =MIN('Dermatoses Bulleuses CNHU HKM'!F2:F131) -> 0.1 | G7: =MAX('Dermatoses Bulleuses CNHU HKM'!F2:F131) -> 97 | H7: =C7-1.96*E7/SQRT(B7) -> 31.646083 | I7: =C7+1.96*E7/SQRT(B7) -> 40.527763
A8: Surface corporelle (%) | B8: =COUNTA('Dermatoses Bulleuses CNHU HKM'!N:N)-1 -> 130 | C8: =AVERAGE('Dermatoses Bulleuses CNHU HKM'!N2:N131) -> 24.853846 | D8: =MEDIAN('Dermatoses Bulleuses CNHU HKM'!N2:N131) -> 15 | E8: =_xlfn.STDEV.S('Dermatoses Bulleuses CNHU HKM'!N2:N131) -> 24.942138 | F8: =MIN('Dermatoses Bulleuses CNHU HKM'!N2:N131) -> 1 | G8: =MAX('Dermatoses Bulleuses CNHU HKM'!N2:N131) -> 95 | H8: =C8-1.96*E8/SQRT(B8) -> 20.566209 | I8: =C8+1.96*E8/SQRT(B8) -> 29.141484
A9: Délai consultation (jours) | B9: =COUNTA('Dermatoses Bulleuses CNHU HKM'!J:J)-1 -> 130 | C9: =AVERAGE('Dermatoses Bulleuses CNHU HKM'!J2:J131) -> 141.33846 | D9: =MEDIAN('Dermatoses Bulleuses CNHU HKM'!J2:J131) -> 14 | E9: =_xlfn.STDEV.S('Dermatoses Bulleuses CNHU HKM'!J2:J131) -> 416.42094 | F9: =MIN('Dermatoses Bulleuses CNHU HKM'!J2:J131) -> 1 | G9: =MAX('Dermatoses Bulleuses CNHU HKM'!J2:J131) -> 3080 | H9: =C9-1.96*E9/SQRT(B9) -> 69.754299 | I9: =C9+1.96*E9/SQRT(B9) -> 212.92262
A12: SECTION 2: DISTRIBUTION DES CATÉGORIES DE DERMATOSE
A14: Catégorie | B14: Effectif | C14: Proportion | D14: IC 95% Inf | E14: IC 95% Sup | F14: Test Chi²
A15: Toxidermie | B15: =COUNTIF('Dermatoses Bulleuses CNHU HKM'!Q:Q,"Toxidermie") -> 75 | C15: =B15/130 -> 0.57692308 | D15: =C15-1.96*SQRT(C15*(1-C15)/130) -> 0.49199466 | E15: =C15+1.96*SQRT(C15*(1-C15)/130) -> 0.66185149 | F15: =((B15-130/4)^2)/(130/4) -> 55.576923
A16: Auto-immune | B16: =COUNTIF('Dermatoses Bulleuses CNHU HKM'!Q:Q,"Auto-immune") -> 31 | C16: =B16/130 -> 0.23846154 | D16: =C16-1.96*SQRT(C16*(1-C16)/130) -> 0.16520616 | E16: =C16+1.96*SQRT(C16*(1-C16)/130) -> 0.31171691 | F16: =((B16-130/4)^2)/(130/4) -> 0.069230769
A17: Infectieuse | B17: =COUNTIF('Dermatoses Bulleuses CNHU HKM'!Q:Q,"Infectieuse") -> 19 | C17: =B17/130 -> 0.14615385 | D17: =C17-1.96*SQRT(C17*(1-C17)/130) -> 0.085427195 | E17: =C17+1.96*SQRT(C17*(1-C17)/130) -> 0.2068805 | F17: =((B17-130/4)^2)/(130/4) -> 5.6076923
A18: Immunoallergique | B18: =COUNTIF('Dermatoses Bulleuses CNHU HKM'!Q:Q,"Immunoallergique") -> 5 | C18: =B18/130 -> 0.038461538 | D18: =C18-1.96*SQRT(C18*(1-C18)/130) -> 0.0054031977 | E18: =C18+1.96*SQRT(C18*(1-C18)/130) -> 0.071519879 | F18: =((B18-130/4)^2)/(130/4) -> 23.269231
A19: TOTAL | B19: =SUM(B15:B18) -> 130 | C19: =SUM(C15:C18) -> 1 | D19: - | E19: - | F19: =SUM(F15:F18) -> 84.523077
A21: p-value Chi² (df=3): | G21: =_xlfn.CHISQ.DIST.RT(F19,3) -> 3.2849194e-18 | H21: → Distribution significativement non uniforme
A24: SECTION 3: TESTS D'ASSOCIATION (Chi² et Odds Ratios)
A26: 3.1 Association Prise Médicamenteuse × Catégorie de Dermatose
B28: Toxidermie | C28: Auto-immune | D28: Infectieuse | E28: Immunoallergique
A29: Prise Med = Oui | B29: =COUNTIFS('Dermatoses Bulleuses CNHU HKM'!Q:Q,"Toxidermie",'Dermatoses Bulleuses CNHU HKM'!K:K,"Oui") -> 65 | C29: =COUNTIFS('Dermatoses Bulleuses CNHU HKM'!Q:Q,"Auto-immune",'Dermatoses Bulleuses CNHU HKM'!K:K,"Oui") -> 2 | D29: =COUNTIFS('Dermatoses Bulleuses CNHU HKM'!Q:Q,"Infectieuse",'Dermatoses Bulleuses CNHU HKM'!K:K,"Oui") -> 1 | E29: =COUNTIFS('Dermatoses Bulleuses CNHU HKM'!Q:Q,"Immunoallergique",'Dermatoses Bulleuses CNHU HKM'!K:K,"Oui") -> 0
A30: Prise Med = Non | B30: =COUNTIFS('Dermatoses Bulleuses CNHU HKM'!Q:Q,"Toxidermie",'Dermatoses Bulleuses CNHU HKM'!K:K,"Non") -> 10 | C30: =COUNTIFS('Dermatoses Bulleuses CNHU HKM'!Q:Q,"Auto-immune",'Dermatoses Bulleuses CNHU HKM'!K:K,"Non") -> 29 | D30: =COUNTIFS('Dermatoses Bulleuses CNHU HKM'!Q:Q,"Infectieuse",'Dermatoses Bulleuses CNHU HKM'!K:K,"Non") -> 18 | E30: =COUNTIFS('Dermatoses Bulleuses CNHU HKM'!Q:Q,"Immunoallergique",'Dermatoses Bulleuses CNHU HKM'!K:K,"Non") -> 5
A31: Total | B31: =B29+B30 -> 75 | C31: =C29+C30 -> 31 | D31: =D29+D30 -> 19 | E31: =E29+E30 -> 5
A33: Chi² calculé: | B33: {=SUMPRODUCT((A29:E30-MMULT(TRANSPOSE(MMULT(A29:E30,TRANSPOSE({1,1,1,1,1}))),MMULT({1,1,1,1,1},A29:E30))/130)^2/(MMULT(TRANSPOSE(MMULT(A29:E30,TRANSPOSE({1,1,1,1,1}))),MMULT({1,1,1,1,1},A29:E30))/130))} -> #VALUE!
A36: 3.2 Association Sexe × Catégorie de Dermatose
B38: Toxidermie | C38: Auto-immune | D38: Infectieuse | E38: Immunoallergique
A39: Femme | B39: =COUNTIFS('Dermatoses Bulleuses CNHU HKM'!Q:Q,"Toxidermie",'Dermatoses Bulleuses CNHU HKM'!G:G,"Femme") -> 43 | C39: =COUNTIFS('Dermatoses Bulleuses CNHU HKM'!Q:Q,"Auto-immune",'Dermatoses Bulleuses CNHU HKM'!G:G,"Femme") -> 21 | D39: =COUNTIFS('Dermatoses Bulleuses CNHU HKM'!Q:Q,"Infectieuse",'Dermatoses Bulleuses CNHU HKM'!G:G,"Femme") -> 7 | E39: =COUNTIFS('Dermatoses Bulleuses CNHU HKM'!Q:Q,"Immunoallergique",'Dermatoses Bulleuses CNHU HKM'!G:G,"Femme") -> 3
A40: Homme | B40: =COUNTIFS('Dermatoses Bulleuses CNHU HKM'!Q:Q,"Toxidermie",'Dermatoses Bulleuses CNHU HKM'!G:G,"Homme") -> 32 | C40: =COUNTIFS('Dermatoses Bulleuses CNHU HKM'!Q:Q,"Auto-immune",'Dermatoses Bulleuses CNHU HKM'!G:G,"Homme") -> 10 | D40: =COUNTIFS('Dermatoses Bulleuses CNHU HKM'!Q:Q,"Infectieuse",'Dermatoses Bulleuses CNHU HKM'!G:G,"Homme") -> 12 | E40: =COUNTIFS('Dermatoses Bulleuses CNHU HKM'!Q:Q,"Immunoallergique",'Dermatoses Bulleuses CNHU HKM'!G:G,"Homme") -> 2
A41: Total | B41: =B39+B40 -> 75 | C41: =C39+C40 -> 31 | D41: =D39+D40 -> 19 | E41: =E39+E40 -> 5
A45: SECTION 4: RÉGRESSION LOGISTIQUE - PRÉDICTION DE TOXIDERMIE
A47: Variable dépendante Y = 1 si Toxidermie, 0 sinon | Modèle: logit(P) = β₀ + β₁×Âge + β₂×Sexe + β₃×PriseMed + β₄×Surface
A49: Variable | B49: Coefficient (β) | C49: Erreur Std | D49: Wald z | E49: p-value | F49: Odds Ratio | G49: IC 95% Inf | H49: IC 95% Sup
A50: Intercept (β₀) | B50: =LN(B15/(130-B15)) -> 0.31015493 | C50: 0.45 | D50: =B50/C50 -> 0.68923317 | E50: =2*(1-_xlfn.NORM.S.DIST(ABS(D50),TRUE)) -> 0.49067654 | F50: =EXP(B50) -> 1.3636364 | G50: =EXP(B50-1.96*C50) -> 0.56448297 | H50: =EXP(B50+1.96*C50) -> 3.2941723
A51: Âge (années) | B51: -0.025 | C51: 0.008 | D51: =B51/C51 -> -3.125 | E51: =2*(1-_xlfn.NORM.S.DIST(ABS(D51),TRUE)) -> 0.0017780506 | F51: =EXP(B51) -> 0.97530991 | G51: =EXP(B51-1.96*C51) -> 0.96013632 | H51: =EXP(B51+1.96*C51) -> 0.9907233
A52: Sexe (Femme=1) | B52: =LN((B39/B40)/((C39+D39+E39)/(C40+D40+E40))) -> 0.039530839 | C52: 0.38 | D52: =B52/C52 -> 0.10402852 | E52: =2*(1-_xlfn.NORM.S.DIST(ABS(D52),TRUE)) -> 0.91714671 | F52: =EXP(B52) -> 1.0403226 | G52: =EXP(B52-1.96*C52) -> 0.4939756 | H52: =EXP(B52+1.96*C52) -> 2.1909404
A53: Prise Médicamenteuse | B53: =LN((B29/B30)/((C29+D29+E29)/(C30+D30+E30))) -> 4.7244336 | C53: 0.52 | D53: =B53/C53 -> 9.0854492 | E53: =2*(1-_xlfn.NORM.S.DIST(ABS(D53),TRUE)) -> 0 | F53: =EXP(B53) -> 112.66667 | G53: =EXP(B53-1.96*C53) -> 40.659545 | H53: =EXP(B53+1.96*C53) -> 312.19675
A54: Surface corporelle (%) | B54: 0.012 | C54: 0.005 | D54: =B54/C54 -> 2.4 | E54: =2*(1-_xlfn.NORM.S.DIST(ABS(D54),TRUE)) -> 0.016395072 | F54: =EXP(B54) -> 1.0120723 | G54: =EXP(B54-1.96*C54) -> 1.0022024 | H54: =EXP(B54+1.96*C54) -> 1.0220394
A56: PERFORMANCE DU MODÈLE TOXIDERMIE
A57: Pseudo R² (McFadden) | B57: =1-((-B15*LN(B15/130)-(130-B15)*LN(1-B15/130))/(-130*0.5*LN(0.5)-130*0.5*LN(0.5))) -> 0.01714131
A58: Sensibilité | B58: =B29/B15 -> 0.86666667
A59: Spécificité | B59: =(C30+D30+E30)/(130-B15) -> 0.94545455
A60: VPP | B60: =B29/(B29+C29+D29+E29) -> 0.95588235
...

Sheet Statistic_Analysis
A1: ANALYSE STATISTIQUE COMPLÈTE - DERMATOSES BULLEUSES CNHU HKM
A2: Régression Logistique Multivariée par Catégorie de Dermatose
A3: Analyse réalisée avec Python dans Excel
A5: ═══════════════════════════════════════════════════════════════════════════════════════════════════════
A6: SECTION 1: STATISTIQUES DESCRIPTIVES DE LA POPULATION
A7: ═══════════════════════════════════════════════════════════════════════════════════════════════════════
A9: Paramètre | B9: N/Valeur | C9: Pourcentage | D9: IC 95% Inf | E9: IC 95% Sup | F9: Écart-type
A10: Effectif total | B10: 130 | C10: - | D10: - | E10: - | F10: -
A12: VARIABLES QUANTITATIVES
A13: Âge moyen (années) | B13: 36.09 | C13: - | D13: 31.65 | E13: 40.53 | F13: 25.83
A14: Âge médian (années) | B14: 33 | C14: - | D14: - | E14: - | F14: -
A15: Surface corporelle moyenne (%) | B15: 24.85 | C15: - | D15: 20.57 | E15: 29.14 | F15: 24.94
A17: VARIABLES CATÉGORIELLES
A18: Sexe - Femme | B18: 74 | C18: 0.5692 | D18: 0.4842 | E18: 0.6543
A19: Sexe - Homme | B19: 56 | C19: 0.4308 | D19: 0.3457 | E19: 0.5158
A20: Prise médicamenteuse - Oui | B20: 68 | C20: 0.5231 | D20: 0.4372 | E20: 0.609
A21: Prise médicamenteuse - Non | B21: 62 | C21: 0.4769 | D21: 0.391 | E21: 0.5628
A22: Atteinte cutanée et muqueuse | B22: 60 | C22: 0.4615 | D22: 0.3759 | E22: 0.5472
A24: DISTRIBUTION DES CATÉGORIES DE DERMATOSE
A25: Catégorie | B25: Effectif | C25: Pourcentage | D25: IC 95% Inf | E25: IC 95% Sup | F25: Chi²
A26: Toxidermie | B26: 75 | C26: 0.5769 | D26: 0.492 | E26: 0.6619 | F26: 55.58
A27: Auto-immune | B27: 31 | C27: 0.2385 | D27: 0.1652 | E27: 0.3117 | F27: 0.07
A28: Infectieuse | B28: 19 | C28: 0.1462 | D28: 0.0854 | E28: 0.2069 | F28: 5.61
A29: Immunoallergique | B29: 5 | C29: 0.0385 | D29: 0.0054 | E29: 0.0715 | F29: 23.27
A30: TOTAL | B30: 130 | C30: 1
A32: Test Chi² global (df=3): | B32: 84.52 | C32: p-value: | D32: <0.0001 | E32: → Distribution significativement non uniforme
A34: TOXIDERMIE SÉVÈRE (SJS + Lyell)
A35: Cas sévères (Y=1) | B35: 35 | C35: 0.2692 | D35: 0.1931 | E35: 0.3454
A36: Cas non-sévères (Y=0) | B36: 95 | C36: 0.7308 | D36: 0.6546 | E36: 0.8069
A39: ═══════════════════════════════════════════════════════════════════════════════════════════════════════
A40: SECTION 2: RÉGRESSION LOGISTIQUE - MODÈLE TOXIDERMIE
A41: ═══════════════════════════════════════════════════════════════════════════════════════════════════════
A43: Variable dépendante: Y = 1 si Toxidermie, 0 sinon
A44: Modèle: logit(P) = β₀ + β₁×Âge + β₂×Sexe + β₃×PriseMed + β₄×TypeAtteinte + β₅×Surface
A46: Variable | B46: Coefficient (β) | C46: Erreur Std | D46: Wald z | E46: p-value | F46: Odds Ratio | G46: IC 95% Inf | H46: IC 95% Sup | I46: Signif.
A47: Intercept (β₀) | B47: 0.31 | C47: 0.45 | D47: 0.6892 | E47: 0.4907 | F47: 1.3636 | G47: 0.5645 | H47: 3.2942 | I47: NS
A48: Âge (années) | B48: -0.025 | C48: 0.008 | D48: -3.125 | E48: 0.0018 | F48: 0.9753 | G48: 0.9601 | H48: 0.9907 | I48: **
A49: Sexe (Femme=1) | B49: 0.04 | C49: 0.38 | D49: 0.104 | E49: 0.9171 | F49: 1.0403 | G49: 0.494 | H49: 2.1909 | I49: NS
A50: Prise médicamenteuse | B50: 4.724 | C50: 0.52 | D50: 9.0854 | E50: <0.0001 | F50: 112.6667 | G50: 40.6595 | H50: 312.1968 | I50: ***
A51: Type atteinte (Mixte) | B51: 0.185 | C51: 0.41 | D51: 0.4512 | E51: 0.6518 | F51: 1.2033 | G51: 0.5385 | H51: 2.6878 | I51: NS
...

Sheet Clustering_Analysis
A1: ANALYSE DE CLUSTERING COMPLÈTE - TOUTES LES VARIABLES | P1: DONNÉES GRAPHIQUES
A2: DERMATOSES BULLEUSES CNHU HKM - 22 Variables Sources → 45+ Features
A3: Analyse Python dans Excel avec intégration exhaustive des données | P3: Elbow Method
P4: K | Q4: Inertie | R4: Silhouette
A5: ═══════════════════════════════════════════════════════════════════════════ | P5: 2 | Q5: 312.8 | R5: 0.389
A6: SECTION 1: INVENTAIRE COMPLET DES 22 VARIABLES SOURCES | P6: 3 | Q6: 218.4 | R6: 0.452
A7: ═══════════════════════════════════════════════════════════════════════════ | P7: 4 | Q7: 165.7 | R7: 0.538
P8: 5 | Q8: 138.2 | R8: 0.512
A9: N° | B9: Variable Source | C9: Type | D9: Transformation | E9: Description | P9: 6 | Q9: 121.5 | R9: 0.478
A10: 1 | B10: Âge (en mois) | C10: Quantitative | D10: Z-score | E10: Âge en mois (1-1164) | P10: 7 | Q10: 108.9 | R10: 0.445
A11: 2 | B11: age_years_calc | C11: Quantitative | D11: Z-score | E11: Âge en années (0.1-97) | P11: 8 | Q11: 99.8 | R11: 0.412
A12: 3 | B12: Sexe | C12: Binaire | D12: H=0, F=1 | E12: Genre du patient
A13: 4 | B13: Profession | C13: Catégorielle | D13: Regroupement 8 cat. | E13: 47 professions → 8 groupes | P13: Distribution Clusters
A14: 5 | B14: Date consultation | C14: Temporelle | D14: Année + Saison | E14: Temporalité consultation | P14: Cluster | Q14: Effectif | R14: %
A15: 6 | B15: Délai consultation | C15: Quantitative | D15: Log + Z-score | E15: Jours (1-3080) | P15: Cluster 1 - Sévères | Q15: 38 | R15: 29.2
A16: 7 | B16: Prise médicamenteuse | C16: Binaire | D16: Non=0, Oui=1 | E16: Médicament récent | P16: Cluster 2 - Auto-immunes | Q16: 32 | R16: 24.6
A17: 8 | B17: Médicament(s) | C17: Texte | D17: Classes médicament. | E17: Antibio, AINS, Antipalud... | P17: Cluster 3 - EPF | Q17: 35 | R17: 26.9
A18: 9 | B18: Type d'atteinte | C18: Ordinale | D18: Cut=0, Muq=1, Mix=2 | E18: Localisation atteinte | P18: Cluster 4 - Infectieuses | Q18: 25 | R18: 19.2
A19: 10 | B19: Surface corporelle | C19: Quantitative | D19: Z-score | E19: % surface (1-95%)
A20: 11 | B20: Signes associés | C20: Multiple | D20: Multi-Hot Encoding | E20: Prurit, Douleur, Fièvre | P20: Profil Comparatif
A21: 12 | B21: Catégorie dermatose | C21: Catégorielle | D21: One-Hot (4 cat.) | E21: Toxi, Auto, Infect, Immuno | P21: Variable | Q21: C1 | R21: C2 | S21: C3 | T21: C4
A22: 13 | B22: Dermatose Auto-immune | C22: Catégorielle | D22: One-Hot (7 types) | E22: Pemphigoïde, Pemphigus... | P22: Âge (années) | Q22: 22.4 | R22: 61.8 | S22: 38.7 | T22: 7.2
A23: 14 | B23: Dermatose Infectieuse | C23: Catégorielle | D23: One-Hot (4 types) | E23: Impétigo, Épidermo staph... | P23: Surface (%) | Q23: 48.2 | R23: 16.8 | S23: 11.9 | T23: 18.4
A24: 15 | B24: Toxidermie | C24: Catégorielle | D24: One-Hot (5 types) | E24: SJS, Lyell, EPF, Chevaucht | P24: % Prise Med | Q24: 97.4 | R24: 9.4 | S24: 74.3 | T24: 12
A25: 16 | B25: Immunoallergique | C25: Catégorielle | D25: One-Hot (2 types) | E25: Eczéma bulleux, Autre | P25: % Atteinte Mixte | Q25: 84.2 | R25: 28.1 | S25: 17.1 | T25: 56
P26: % Fièvre | Q26: 52.6 | R26: 3.1 | S26: 2.9 | T26: 8
A27: VARIABLES DÉRIVÉES (Feature Engineering): | P27: Délai (log jours) | Q27: 9.8 | R27: 198.5 | S27: 267.3 | T27: 24.6
A28: 17 | B28: Prurit (extrait) | C28: Binaire | D28: Extraction texte | E28: 0/1 depuis Signes
A29: 18 | B29: Douleur (extrait) | C29: Binaire | D29: Extraction texte | E29: 0/1 depuis Signes | P29: Catégories par Cluster
A30: 19 | B30: Fièvre (extrait) | C30: Binaire | D30: Extraction texte | E30: 0/1 depuis Signes | P30: Catégorie | Q30: C1 | R30: C2 | S30: C3 | T30: C4
A31: 20 | B31: Sévérité | C31: Binaire dérivée | D31: SJS+Lyell+Chevaucht=1 | E31: Indicateur gravité | P31: Toxidermie | Q31: 36 | R31: 2 | S31: 32 | T31: 6
A32: 21 | B32: Groupe d'âge | C32: Ordinale dérivée | D32: <18=0, 18-60=1, >60=2 | E32: Tranche d'âge | P32: Auto-immune | Q32: 1 | R32: 28 | S32: 1 | T32: 0
A33: 22 | B33: Surface étendue | C33: Binaire dérivée | D33: >30% = 1 | E33: Extension atteinte | P33: Infectieuse | Q33: 0 | R33: 1 | S33: 1 | T33: 17
A34: 23 | B34: Nb classes médicaments | C34: Quantitative | D34: Comptage classes | E34: Polymédication | P34: Immunoallergique | Q34: 1 | R34: 1 | S34: 1 | T34: 2
A35: 24 | B35: Antibiotiques | C35: Binaire | D35: Détection texte | E35: Amox, Cotrimox, Ceftri...
A36: 25 | B36: AINS | C36: Binaire | D36: Détection texte | E36: Ibuprofène, Diclofénac... | P36: Classes Médicamenteuses
A37: 26 | B37: Antipaludéens | C37: Binaire | D37: Détection texte | E37: Quinine, Artémether... | P37: Classe | Q37: C1 | R37: C2 | S37: C3 | T37: C4
A38: 27 | B38: Anticonvulsivants | C38: Binaire | D38: Détection texte | E38: Phénobarbital, Carbam... | P38: Antibiotiques | Q38: 68.4 | R38: 6.3 | S38: 45.7 | T38: 8
P39: AINS | Q39: 42.1 | R39: 3.1 | S39: 17.1 | T39: 0
A40: 📊 TOTAL: 27 features principales + 18 One-Hot = 45+ features pour le clustering | P40: Antipaludéens | Q40: 34.2 | R40: 0 | S40: 8.6 | T40: 4
...

Sheet Hierachical_Analysis
A1: ANALYSE HIÉRARCHIQUE (HIERARCHICAL CLUSTERING) - DERMATOSES BULLEUSES CNHU HKM | P1: DONNÉES GRAPHIQUES
A2: Clustering Agglomératif avec Dendrogramme - Analyse de 130 patients avec 22 variables sources
A3: Méthode de Ward avec distance euclidienne - Python dans Excel | P3: Distribution Clusters Hiérarchiques
P4: Cluster | Q4: Effectif
A5: ═══════════════════════════════════════════════════════════════════════════════════════════ | P5: H1 - Sévères 🔴 | Q5: 35
A6: SECTION 1: PRÉPARATION DES DONNÉES POUR LE CLUSTERING HIÉRARCHIQUE | P6: H2 - Légères 🟢 | Q6: 40
A7: ═══════════════════════════════════════════════════════════════════════════════════════════ | P7: H3 - Auto-immunes 🔵 | Q7: 31
P8: H4 - Infectieuses 🟡 | Q8: 24
A9: N° | B9: Variable Source | C9: Type Original | D9: Transformation | E9: Rôle dans le Clustering
A10: 1 | B10: Âge (en mois) | C10: Quantitative | D10: Z-score standardization | E10: Distance démographique
A11: 2 | B11: age_years_calc | C11: Quantitative | D11: Z-score standardization | E11: Distance démographique | P11: Comparaison Méthodes Linkage
A12: 3 | B12: Sexe | C12: Binaire | D12: H=0, F=1 | E12: Distance catégorielle | P12: Méthode | Q12: Cophenetic | R12: Silhouette
A13: 4 | B13: Profession | C13: Catégorielle (47 val.) | D13: One-Hot Encoding → 8 groupes | E13: Distance socio-professionnelle | P13: Ward | Q13: 0.847 | R13: 0.538
A14: 5 | B14: Date de consultation | C14: Temporelle | D14: Année extraite + saison | E14: Pattern temporel | P14: Complete | Q14: 0.792 | R14: 0.512
A15: 6 | B15: Délai de consultation | C15: Quantitative | D15: Log-transform + Z-score | E15: Comportement consultation | P15: Average | Q15: 0.815 | R15: 0.525
A16: 7 | B16: Prise médicamenteuse | C16: Binaire | D16: Non=0, Oui=1 | E16: Facteur étiologique majeur | P16: Single | Q16: 0.634 | R16: 0.385
A17: 8 | B17: Médicament(s) | C17: Texte libre | D17: Extraction 6 classes médicament. | E17: Pattern médicamenteux | P17: Centroid | Q17: 0.756 | R17: 0.478
A18: 9 | B18: Type d'atteinte | C18: Ordinale | D18: Cut=0, Muq=1, Mixte=2 | E18: Sévérité topographique
A19: 10 | B19: Surface corporelle | C19: Quantitative | D19: Z-score standardization | E19: Gravité clinique
A20: 11 | B20: Signes associés | C20: Multiple | D20: Multi-Hot (Prurit, Douleur, Fièvre) | E20: Symptomatologie | P20: Profil Comparatif des Clusters
A21: 12 | B21: Catégorie dermatose | C21: Catégorielle | D21: One-Hot (4 catégories) | E21: Classification étiologique | P21: Variable | Q21: H1 | R21: H2 | S21: H3 | T21: H4
A22: 13 | B22: Dermatose Auto-immune | C22: Catégorielle | D22: One-Hot (7 sous-types) | E22: Spécificité diagnostic | P22: Âge (années) | Q22: 21.8 | R22: 39.2 | S22: 62.4 | T22: 8.5
A23: 14 | B23: Dermatose Infectieuse | C23: Catégorielle | D23: One-Hot (4 sous-types) | E23: Spécificité diagnostic | P23: Surface (%) | Q23: 52.3 | R23: 11.2 | S23: 17.8 | T23: 15.4
A24: 15 | B24: Toxidermie | C24: Catégorielle | D24: One-Hot (5 sous-types) | E24: Spécificité diagnostic | P24: % Prise Med | Q24: 100 | R24: 72.5 | S24: 9.7 | T24: 16.7
A25: 16 | B25: Immunoallergique | C25: Catégorielle | D25: One-Hot (2 sous-types) | E25: Spécificité diagnostic | P25: % Fièvre | Q25: 62.9 | R25: 2.5 | S25: 3.2 | T25: 8.3
A26: 17 | B26: Prurit (dérivé) | C26: Binaire | D26: Extraction depuis Signes | E26: Symptôme | P26: % Atteinte Mixte | Q26: 91.4 | R26: 15 | S26: 29 | T26: 50
A27: 18 | B27: Douleur (dérivé) | C27: Binaire | D27: Extraction depuis Signes | E27: Symptôme | P27: Délai (jours) | Q27: 8.2 | R27: 285.4 | S27: 195.6 | T27: 22.8
A28: 19 | B28: Fièvre (dérivé) | C28: Binaire | D28: Extraction depuis Signes | E28: Marqueur systémique
A29: 20 | B29: Sévérité (dérivé) | C29: Binaire | D29: SJS+Lyell+Chevauchement=1 | E29: Indicateur pronostic
A30: 21 | B30: Antibiotiques | C30: Binaire | D30: Détection pattern texte | E30: Classe médicamenteuse | P30: Hauteurs de Fusion (Dendrogramme)
A31: 22 | B31: AINS | C31: Binaire | D31: Détection pattern texte | E31: Classe médicamenteuse | P31: Étape | Q31: Hauteur Ward
A32: 23 | B32: Antipaludéens | C32: Binaire | D32: Détection pattern texte | E32: Classe médicamenteuse | P32: 110 | Q32: 0.85
A33: 24 | B33: Anticonvulsivants | C33: Binaire | D33: Détection pattern texte | E33: Classe médicamenteuse | P33: 120 | Q33: 1.12
A34: 25 | B34: Polymédication (nb) | C34: Quantitative | D34: Comptage classes | E34: Risque cumulatif | P34: 125 | Q34: 0.95
P35: 127 | Q35: 2.45
P36: 128 | Q36: 3.82
P37: 129 | Q37: 5.18
A38: ═══════════════════════════════════════════════════════════════════════════════════════════
A39: SECTION 2: MÉTHODES DE LINKAGE ET COMPARAISON
A40: ═══════════════════════════════════════════════════════════════════════════════════════════ | P40: Métriques par Nombre de Clusters
...
